Workbook

Sheet Historico_Cota
A1: Data | B1: Ibovespa Fechamento | C1: Patrimônio | D1: Cota | E1: Rent - Kairos | F1: Rent - Ibov | G1: Acum - Kairos | H1: Acum - Ibov | I1: MêsAno | J1: Mês - Kairos | K1: Mês - Ibov | L1: Cota 100 - Kairos | M1: Cota 100 - Ibov
A2: 45327 | B2: 127593.49 | C2: 308855.71 | D2: 1.7860873 | E2: -4.2e-05 | F2: 0 | G2: 0 | H2: 0 | I2: =TEXT(A2,"mmaaaa") -> 022024 | J2: 0 | K2: 0 | L2: 100 | M2: 100
A3: 45328 | B3: 130416.31 | C3: 315784.41 | D3: 1.8261554 | E3: =D3/D2-1 -> 0.02243345 | F3: =B3/B2-1 -> 0.022123543 | G3: =D3/$D$2-1 -> 0.02243345 | H3: =B3/$B$2-1 -> 0.022123543 | I3: =TEXT(A3,"mmaaaa") -> 022024 | J3: =E3 -> 0.02243345 | K3: =F3 -> 0.022123543 | L3: =L2*(1+E3) -> 102.24334 | M3: =M2*(1+F3) -> 102.21235
A4: 45329 | B4: 129949.9 | C4: 318045.64 | D4: 1.8392319 | E4: =D4/D3-1 -> 0.0071606775 | F4: =B4/B3-1 -> -0.0035763165 | G4: =D4/$D$2-1 -> 0.029754766 | H4: =B4/$B$2-1 -> 0.018468105 | I4: =TEXT(A4,"mmaaaa") -> 022024 | J4: =IF(I4=I3,(1+E4)*(1+J3)-1,E4) -> 0.029754766 | K4: =IF(I4=I3,(1+F4)*(1+K3)-1,F4) -> 0.018468105 | L4: =L3*(1+E4) -> 102.97548 | M4: =M3*(1+F4) -> 101.84681
A5: 45330 | B5: 128216.92 | C5: 312441.93 | D5: 1.8068261 | E5: =D5/D4-1 -> -0.017619203 | F5: =B5/B4-1 -> -0.013335755 | G5: =D5/$D$2-1 -> 0.011611308 | H5: =B5/$B$2-1 -> 0.0048860643 | I5: =TEXT(A5,"mmaaaa") -> 022024 | J5: =IF(I5=I4,(1+E5)*(1+J4)-1,E5) -> 0.011611308 | K5: =IF(I5=I4,(1+F5)*(1+K4)-1,F5) -> 0.0048860643 | L5: =L4*(1+E5) -> 101.16113 | M5: =M4*(1+F5) -> 100.48861
A6: 45331 | B6: 128025.7 | C6: 311124.35 | D6: 1.7992067 | E6: =D6/D5-1 -> -0.0042170355 | F6: =B6/B5-1 -> -0.0014913788 | G6: =D6/$D$2-1 -> 0.0073453072 | H6: =B6/$B$2-1 -> 0.0033873985 | I6: =TEXT(A6,"mmaaaa") -> 022024 | J6: =IF(I6=I5,(1+E6)*(1+J5)-1,E6) -> 0.0073453072 | K6: =IF(I6=I5,(1+F6)*(1+K5)-1,F6) -> 0.0033873985 | L6: =L5*(1+E6) -> 100.73453 | M6: =M5*(1+F6) -> 100.33874
A7: 45336 | B7: 127018.29 | C7: 309971.43 | D7: 1.7925394 | E7: =D7/D6-1 -> -0.0037056554 | F7: =B7/B6-1 -> -0.0078688107 | G7: =D7/$D$2-1 -> 0.0036124326 | H7: =B7/$B$2-1 -> -0.004508067 | I7: =TEXT(A7,"mmaaaa") -> 022024 | J7: =IF(I7=I6,(1+E7)*(1+J6)-1,E7) -> 0.0036124326 | K7: =IF(I7=I6,(1+F7)*(1+K6)-1,F7) -> -0.004508067 | L7: =L6*(1+E7) -> 100.36124 | M7: =M6*(1+F7) -> 99.549193
A8: 45337 | B8: 127804.13 | C8: 310775.21 | D8: 1.7971876 | E8: =D8/D7-1 -> 0.0025930754 | F8: =B8/B7-1 -> 0.0061868255 | G8: =D8/$D$2-1 -> 0.0062148753 | H8: =B8/$B$2-1 -> 0.0016508679 | I8: =TEXT(A8,"mmaaaa") -> 022024 | J8: =IF(I8=I7,(1+E8)*(1+J7)-1,E8) -> 0.0062148753 | K8: =IF(I8=I7,(1+F8)*(1+K7)-1,F8) -> 0.0016508679 | L8: =L7*(1+E8) -> 100.62149 | M8: =M7*(1+F8) -> 100.16509
A9: 45338 | B9: 128725.88 | C9: 311510.75 | D9: 1.8014412 | E9: =D9/D8-1 -> 0.0023667924 | F9: =B9/B8-1 -> 0.0072122082 | G9: =D9/$D$2-1 -> 0.008596377 | H9: =B9/$B$2-1 -> 0.0088749826 | I9: =TEXT(A9,"mmaaaa") -> 022024 | J9: =IF(I9=I8,(1+E9)*(1+J8)-1,E9) -> 0.008596377 | K9: =IF(I9=I8,(1+F9)*(1+K8)-1,F9) -> 0.0088749826 | L9: =L8*(1+E9) -> 100.85964 | M9: =M8*(1+F9) -> 100.8875
A10: 45341 | B10: 129035.74 | C10: 314070.32 | D10: 1.816243 | E10: =D10/D9-1 -> 0.0082166323 | F10: =B10/B9-1 -> 0.0024071306 | G10: =D10/$D$2-1 -> 0.016883643 | H10: =B10/$B$2-1 -> 0.011303476 | I10: =TEXT(A10,"mmaaaa") -> 022024 | J10: =IF(I10=I9,(1+E10)*(1+J9)-1,E10) -> 0.016883643 | K10: =IF(I10=I9,(1+F10)*(1+K9)-1,F10) -> 0.011303476 | L10: =L9*(1+E10) -> 101.68836 | M10: =M9*(1+F10) -> 101.13035
A11: 45342 | B11: 129916.11 | C11: 316657.11 | D11: 1.8312022 | E11: =D11/D10-1 -> 0.0082363429 | F11: =B11/B10-1 -> 0.0068226834 | G11: =D11/$D$2-1 -> 0.025259045 | H11: =B11/$B$2-1 -> 0.01820328 | I11: =TEXT(A11,"mmaaaa") -> 022024 | J11: =IF(I11=I10,(1+E11)*(1+J10)-1,E11) -> 0.025259045 | K11: =IF(I11=I10,(1+F11)*(1+K10)-1,F11) -> 0.01820328 | L11: =L10*(1+E11) -> 102.5259 | M11: =M10*(1+F11) -> 101.82033
A12: 45343 | B12: 130031.58 | C12: 316906.17 | D12: 1.8326425 | E12: =D12/D11-1 -> 0.00078652702 | F12: =B12/B11-1 -> 0.00088880432 | G12: =D12/$D$2-1 -> 0.026065439 | H12: =B12/$B$2-1 -> 0.019108263 | I12: =TEXT(A12,"mmaaaa") -> 022024 | J12: =IF(I12=I11,(1+E12)*(1+J11)-1,E12) -> 0.026065439 | K12: =IF(I12=I11,(1+F12)*(1+K11)-1,F12) -> 0.019108263 | L12: =L11*(1+E12) -> 102.60654 | M12: =M11*(1+F12) -> 101.91083
A13: 45344 | B13: 130240.55 | C13: 316595.78 | D13: 1.8308475 | E13: =D13/D12-1 -> -0.00097943818 | F13: =B13/B12-1 -> 0.0016070711 | G13: =D13/$D$2-1 -> 0.025060471 | H13: =B13/$B$2-1 -> 0.020746043 | I13: =TEXT(A13,"mmaaaa") -> 022024 | J13: =IF(I13=I12,(1+E13)*(1+J12)-1,E13) -> 0.025060471 | K13: =IF(I13=I12,(1+F13)*(1+K12)-1,F13) -> 0.020746043 | L13: =L12*(1+E13) -> 102.50605 | M13: =M12*(1+F13) -> 102.0746
A14: 45345 | B14: 129418.73 | C14: 313052.96 | D14: 1.8103597 | E14: =D14/D13-1 -> -0.011190359 | F14: =B14/B13-1 -> -0.0063100164 | G14: =D14/$D$2-1 -> 0.013589677 | H14: =B14/$B$2-1 -> 0.014305119 | I14: =TEXT(A14,"mmaaaa") -> 022024 | J14: =IF(I14=I13,(1+E14)*(1+J13)-1,E14) -> 0.013589677 | K14: =IF(I14=I13,(1+F14)*(1+K13)-1,F14) -> 0.014305119 | L14: =L13*(1+E14) -> 101.35897 | M14: =M13*(1+F14) -> 101.43051
A15: 45348 | B15: 129609.05 | C15: 312493.55 | D15: 1.8071246 | E15: =D15/D14-1 -> -0.0017869488 | F15: =B15/B14-1 -> 0.0014705754 | G15: =D15/$D$2-1 -> 0.011778444 | H15: =B15/$B$2-1 -> 0.015796731 | I15: =TEXT(A15,"mmaaaa") -> 022024 | J15: =IF(I15=I14,(1+E15)*(1+J14)-1,E15) -> 0.011778444 | K15: =IF(I15=I14,(1+F15)*(1+K14)-1,F15) -> 0.015796731 | L15: =L14*(1+E15) -> 101.17784 | M15: =M14*(1+F15) -> 101.57967
... A305: 45769 | B305: 130464 | C305: 118099.56 | D305: 1.7413512 | E305: =D305/D304-1 -> 0.0018976378 | F305: =B305/B304-1 -> 0.006278442 | G305: =D305/$D$2-1 -> -0.025046998 | H305: =B305/$B$2-1 -> 0.022497308 | I305: =TEXT(A305,"mmaaaa") -> 042025 | J305: =IF(I305=I304,(1+E305)*(1+J304)-1,E305) -> -0.020623393 | K305: =IF(I305=I304,(1+F305)*(1+K304)-1,F305) -> 0.0015660986 | L305: =L304*(1+E305) -> 97.4953 | M305: =M304*(1+F305) -> 102.24973
A306: =A305+1 -> 45770 | B306: 132216 | C306: 118888.93 | D306: 1.7529903 | E306: =D306/D305-1 -> 0.0066839368 | F306: =B306/B305-1 -> 0.013428992 | G306: =D306/$D$2-1 -> -0.018530473 | H306: =B306/$B$2-1 -> 0.036228416 | I306: =TEXT(A306,"mmaaaa") -> 042025 | J306: =IF(I306=I305,(1+E306)*(1+J305)-1,E306) -> -0.014077301 | K306: =IF(I306=I305,(1+F306)*(1+K305)-1,F306) -> 0.015016122 | L306: =L305*(1+E306) -> 98.146953 | M306: =M305*(1+F306) -> 103.62284
A307: =A306+1 -> 45771 | B307: 134580 | C307: 120667.53 | D307: 1.7792153 | E307: =D307/D306-1 -> 0.014960182 | F307: =B307/B306-1 -> 0.017879833 | G307: =D307/$D$2-1 -> -0.0038475108 | H307: =B307/$B$2-1 -> 0.054756007 | I307: =TEXT(A307,"mmaaaa") -> 042025 | J307: =IF(I307=I306,(1+E307)*(1+J306)-1,E307) -> 0.00067228134 | K307: =IF(I307=I306,(1+F307)*(1+K306)-1,F307) -> 0.03316444 | L307: =L306*(1+E307) -> 99.615249 | M307: =M306*(1+F307) -> 105.4756
A308: =A307+1 -> 45772 | B308: 134739 | C308: 120872.73 | D308: 1.782241 | E308: =D308/D307-1 -> 0.0017005403 | F308: =B308/B307-1 -> 0.0011814534 | G308: =D308/$D$2-1 -> -0.0021535134 | H308: =B308/$B$2-1 -> 0.056002152 | I308: =TEXT(A308,"mmaaaa") -> 042025 | J308: =IF(I308=I307,(1+E308)*(1+J307)-1,E308) -> 0.0023739649 | K308: =IF(I308=I307,(1+F308)*(1+K307)-1,F308) -> 0.034385076 | L308: =L307*(1+E308) -> 99.784649 | M308: =M307*(1+F308) -> 105.60022
A309: =A308+3 -> 45775 | B309: 135015 | C309: 121042.06 | D309: 1.784737 | E309: =D309/D308-1 -> 0.0014005081 | F309: =B309/B308-1 -> 0.0020484047 | G309: =D309/$D$2-1 -> -0.00075602127 | H309: =B309/$B$2-1 -> 0.058165272 | I309: =TEXT(A309,"mmaaaa") -> 042025 | J309: =IF(I309=I308,(1+E309)*(1+J308)-1,E309) -> 0.0037777978 | K309: =IF(I309=I308,(1+F309)*(1+K308)-1,F309) -> 0.036503915 | L309: =L308*(1+E309) -> 99.924398 | M309: =M308*(1+F309) -> 105.81653
A310: =A309+1 -> 45776 | B310: 135093 | C310: 121544.67 | D310: 1.792148 | E310: =D310/D309-1 -> 0.0041524325 | F310: =B310/B309-1 -> 0.00057771359 | G310: =D310/$D$2-1 -> 0.0033932719 | H310: =B310/$B$2-1 -> 0.058776588 | I310: =TEXT(A310,"mmaaaa") -> 042025 | J310: =IF(I310=I309,(1+E310)*(1+J309)-1,E310) -> 0.0079459174 | K310: =IF(I310=I309,(1+F310)*(1+K309)-1,F310) -> 0.037102718 | L310: =L309*(1+E310) -> 100.33933 | M310: =M309*(1+F310) -> 105.87766
A311: =A310+1 -> 45777 | B311: 135067 | C311: 122186.69 | D311: 1.801615 | E311: =D311/D310-1 -> 0.0052824878 | F311: =B311/B310-1 -> -0.00019246001 | G311: =D311/$D$2-1 -> 0.0086936847 | H311: =B311/$B$2-1 -> 0.058572816 | I311: =TEXT(A311,"mmaaaa") -> 042025 | J311: =IF(I311=I310,(1+E311)*(1+J310)-1,E311) -> 0.013270379 | K311: =IF(I311=I310,(1+F311)*(1+K310)-1,F311) -> 0.036903117 | L311: =L310*(1+E311) -> 100.86937 | M311: =M310*(1+F311) -> 105.85728
A312: =A311+2 -> 45779 | B312: 135134 | C312: 123086.85 | D312: 1.814887 | E312: =D312/D311-1 -> 0.0073667237 | F312: =B312/B311-1 -> 0.00049605011 | G312: =D312/$D$2-1 -> 0.016124452 | H312: =B312/$B$2-1 -> 0.059097921 | I312: =TEXT(A312,"mmaaaa") -> 052025 | J312: =IF(I312=I311,(1+E312)*(1+J311)-1,E312) -> 0.0073667237 | K312: =IF(I312=I311,(1+F312)*(1+K311)-1,F312) -> 0.00049605011 | L312: =L311*(1+E312) -> 101.61245 | M312: =M311*(1+F312) -> 105.90979
A313: =A312+3 -> 45782 | B313: 133491 | C313: 122384.88 | D313: 1.804537 | E313: =D313/D312-1 -> -0.0057028344 | F313: =B313/B312-1 -> -0.012158302 | G313: =D313/$D$2-1 -> 0.010329663 | H313: =B313/$B$2-1 -> 0.046221089 | I313: =TEXT(A313,"mmaaaa") -> 052025 | J313: =IF(I313=I312,(1+E313)*(1+J312)-1,E313) -> 0.0016218781 | K313: =IF(I313=I312,(1+F313)*(1+K312)-1,F313) -> -0.011668283 | L313: =L312*(1+E313) -> 101.03297 | M313: =M312*(1+F313) -> 104.62211
A314: =A313+1 -> 45783 | B314: 133516 | C314: 122177.5 | D314: 1.801479 | E314: =D314/D313-1 -> -0.0016946175 | F314: =B314/B313-1 -> 0.00018727854 | G314: =D314/$D$2-1 -> 0.0086175406 | H314: =B314/$B$2-1 -> 0.046417023 | I314: =TEXT(A314,"mmaaaa") -> 052025 | J314: =IF(I314=I313,(1+E314)*(1+J313)-1,E314) -> -7.5487826e-05 | K314: =IF(I314=I313,(1+F314)*(1+K313)-1,F314) -> -0.01148319 | L314: =L313*(1+E314) -> 100.86175 | M314: =M313*(1+F314) -> 104.6417
A315: =A314+1 -> 45784 | B315: 133398 | C315: 122255.06 | D315: 1.802623 | E315: =D315/D314-1 -> 0.00063503377 | F315: =B315/B314-1 -> -0.00088378921 | G315: =D315/$D$2-1 -> 0.0092580468 | H315: =B315/$B$2-1 -> 0.045492211 | I315: =TEXT(A315,"mmaaaa") -> 052025 | J315: =IF(I315=I314,(1+E315)*(1+J314)-1,E315) -> 0.00055949801 | K315: =IF(I315=I314,(1+F315)*(1+K314)-1,F315) -> -0.01235683 | L315: =L314*(1+E315) -> 100.9258 | M315: =M314*(1+F315) -> 104.54922
A316: =A315+1 -> 45785 | B316: 136232 | C316: 123488.72 | D316: 1.820813 | E316: =D316/D315-1 -> 0.010090851 | F316: =B316/B315-1 -> 0.021244696 | G316: =D316/$D$2-1 -> 0.019442319 | H316: =B316/$B$2-1 -> 0.067703376 | I316: =TEXT(A316,"mmaaaa") -> 052025 | J316: =IF(I316=I315,(1+E316)*(1+J315)-1,E316) -> 0.010655995 | K316: =IF(I316=I315,(1+F316)*(1+K315)-1,F316) -> 0.0086253489 | L316: =L315*(1+E316) -> 101.94423 | M316: =M315*(1+F316) -> 106.77034
A317: =A316+1 -> 45786 | B317: 136512 | C317: 123858.48 | D317: 1.826265 | E317: =D317/D316-1 -> 0.0029942668 | F317: =B317/B316-1 -> 0.0020553174 | G317: =D317/$D$2-1 -> 0.022494802 | H317: =B317/$B$2-1 -> 0.069897845 | I317: =TEXT(A317,"mmaaaa") -> 052025 | J317: =IF(I317=I316,(1+E317)*(1+J316)-1,E317) -> 0.013682168 | K317: =IF(I317=I316,(1+F317)*(1+K316)-1,F317) -> 0.010698394 | L317: =L316*(1+E317) -> 102.24948 | M317: =M316*(1+F317) -> 106.98978
A318: 45789 | B318: 136563 | C318: 124653.35 | D318: 1.837985 | E318: =D318/D317-1 -> 0.0064174695 | F318: =B318/B317-1 -> 0.00037359353 | G318: =D318/$D$2-1 -> 0.029056631 | H318: =B318/$B$2-1 -> 0.070297552 | I318: =TEXT(A318,"mmaaaa") -> 052025 | J318: =IF(I318=I317,(1+E318)*(1+J317)-1,E318) -> 0.020187443 | K318: =IF(I318=I317,(1+F318)*(1+K317)-1,F318) -> 0.011075985 | L318: =L317*(1+E318) -> 102.90566 | M318: =M317*(1+F318) -> 107.02976
A319: =A318+1 -> 45790 | B319: 138963 | C319: 126243.54 | D319: 1.861432 | E319: =D319/D318-1 -> 0.012756905 | F319: =B319/B318-1 -> 0.017574306 | G319: =D319/$D$2-1 -> 0.042184209 | H319: =B319/$B$2-1 -> 0.089107289 | I319: =TEXT(A319,"mmaaaa") -> 052025 | J319: =IF(I319=I318,(1+E319)*(1+J318)-1,E319) -> 0.033201877 | K319: =IF(I319=I318,(1+F319)*(1+K318)-1,F319) -> 0.028844944 | L319: =L318*(1+E319) -> 104.21842 | M319: =M318*(1+F319) -> 108.91073
A320: =A319+1 -> 45791 | B320: 138423 | C320: 126193.97 | D320: 1.8607014 | E320: =D320/D319-1 -> -0.00039247602 | F320: =B320/B319-1 -> -0.0038859265 | G320: =D320/$D$2-1 -> 0.041775176 | H320: =B320/$B$2-1 -> 0.084875098 | I320: =TEXT(A320,"mmaaaa") -> 052025 | J320: =IF(I320=I319,(1+E320)*(1+J319)-1,E320) -> 0.03279637 | K320: =IF(I320=I319,(1+F320)*(1+K319)-1,F320) -> 0.024846928 | L320: =L319*(1+E320) -> 104.17752 | M320: =M319*(1+F320) -> 108.48751
A321: =A320+1 -> 45792 | B321: 139334 | C321: 125977.18 | D321: 1.8575049 | E321: =D321/D320-1 -> -0.0017179109 | F321: =B321/B320-1 -> 0.0065812762 | G321: =D321/$D$2-1 -> 0.039985499 | H321: =B321/$B$2-1 -> 0.092014961 | I321: =TEXT(A321,"mmaaaa") -> 052025 | J321: =IF(I321=I320,(1+E321)*(1+J320)-1,E321) -> 0.031022118 | K321: =IF(I321=I320,(1+F321)*(1+K320)-1,F321) -> 0.031591729 | L321: =L320*(1+E321) -> 103.99855 | M321: =M320*(1+F321) -> 109.2015
A322: =A321+1 -> 45793 | B322: 139187 | C322: 123994.64 | D322: 1.8282728 | E322: =D322/D321-1 -> -0.015737295 | F322: =B322/B321-1 -> -0.0010550189 | G322: =D322/$D$2-1 -> 0.023618941 | H322: =B322/$B$2-1 -> 0.090862865 | I322: =TEXT(A322,"mmaaaa") -> 052025 | J322: =IF(I322=I321,(1+E322)*(1+J321)-1,E322) -> 0.014796619 | K322: =IF(I322=I321,(1+F322)*(1+K321)-1,F322) -> 0.03050338 | L322: =L321*(1+E322) -> 102.36189 | M322: =M321*(1+F322) -> 109.08629
A323: 45796 | B323: 139636 | C323: 124211.27 | D323: 1.831467 | E323: =D323/D322-1 -> 0.0017470916 | F323: =B323/B322-1 -> 0.003225876 | G323: =D323/$D$2-1 -> 0.025407297 | H323: =B323/$B$2-1 -> 0.094381853 | I323: =TEXT(A323,"mmaaaa") -> 052025 | J323: =IF(I323=I322,(1+E323)*(1+J322)-1,E323) -> 0.016569562 | K323: =IF(I323=I322,(1+F323)*(1+K322)-1,F323) -> 0.033827656 | L323: =L322*(1+E323) -> 102.54073 | M323: =M322*(1+F323) -> 109.43819
A324: 45797 | B324: 140020 | C324: 124322.95 | D324: 1.8331137 | E324: =D324/D323-1 -> 0.00089911326 | F324: =B324/B323-1 -> 0.0027500072 | G324: =D324/$D$2-1 -> 0.026329254 | H324: =B324/$B$2-1 -> 0.097391411 | I324: =TEXT(A324,"mmaaaa") -> 052025 | J324: =IF(I324=I323,(1+E324)*(1+J323)-1,E324) -> 0.017483573 | K324: =IF(I324=I323,(1+F324)*(1+K323)-1,F324) -> 0.036670689 | L324: =L323*(1+E324) -> 102.63293 | M324: =M323*(1+F324) -> 109.73914
A325: 45798 | B325: 137881 | C325: 123210.01 | D325: 1.816703 | E325: =D325/D324-1 -> -0.0089523459 | F325: =B325/B324-1 -> -0.015276389 | G325: =D325/$D$2-1 -> 0.0171412 | H325: =B325/$B$2-1 -> 0.080627233 | I325: =TEXT(A325,"mmaaaa") -> 052025 | J325: =IF(I325=I324,(1+E325)*(1+J324)-1,E325) -> 0.0083747082 | K325: =IF(I325=I324,(1+F325)*(1+K324)-1,F325) -> 0.020834105 | L325: =L324*(1+E325) -> 101.71412 | M325: =M324*(1+F325) -> 108.06272
A326: 45799 | B326: 137272 | C326: 122404.61 | D326: 1.804828 | E326: =D326/D325-1 -> -0.0065365665 | F326: =B326/B325-1 -> -0.0044168522 | G326: =D326/$D$2-1 -> 0.010492589 | H326: =B326/$B$2-1 -> 0.075854262 | I326: =TEXT(A326,"mmaaaa") -> 052025 | J326: =IF(I326=I325,(1+E326)*(1+J325)-1,E326) -> 0.0017833999 | K326: =IF(I326=I325,(1+F326)*(1+K325)-1,F326) -> 0.016325231 | L326: =L325*(1+E326) -> 101.04926 | M326: =M325*(1+F326) -> 107.58543
A327: 45800 | B327: 137824 | C327: 122174.07 | D327: 1.801428 | E327: =D327/D326-1 -> -0.001883836 | F327: =B327/B326-1 -> 0.0040212134 | G327: =D327/$D$2-1 -> 0.0085889866 | H327: =B327/$B$2-1 -> 0.080180501 | I327: =TEXT(A327,"mmaaaa") -> 052025 | J327: =IF(I327=I326,(1+E327)*(1+J326)-1,E327) -> -0.00010379576 | K327: =IF(I327=I326,(1+F327)*(1+K326)-1,F327) -> 0.020412092 | L327: =L326*(1+E327) -> 100.8589 | M327: =M326*(1+F327) -> 108.01805
A328: 45803 | B328: 138136 | C328: 122833.87 | D328: 1.811157 | E328: =D328/D327-1 -> 0.0054007154 | F328: =B328/B327-1 -> 0.0022637567 | G328: =D328/$D$2-1 -> 0.014036089 | H328: =B328/$B$2-1 -> 0.082625767 | I328: =TEXT(A328,"mmaaaa") -> 052025 | J328: =IF(I328=I327,(1+E328)*(1+J327)-1,E328) -> 0.0052963591 | K328: =IF(I328=I327,(1+F328)*(1+K327)-1,F328) -> 0.022722056 | L328: =L327*(1+E328) -> 101.40361 | M328: =M327*(1+F328) -> 108.26258
A329: 45804 | B329: 139541 | C329: 123977.38 | D329: 1.828018 | E329: =D329/D328-1 -> 0.0093095187 | F329: =B329/B328-1 -> 0.010171136 | G329: =D329/$D$2-1 -> 0.023476277 | H329: =B329/$B$2-1 -> 0.093637301 | I329: =TEXT(A329,"mmaaaa") -> 052025 | J329: =IF(I329=I328,(1+E329)*(1+J328)-1,E329) -> 0.014655184 | K329: =IF(I329=I328,(1+F329)*(1+K328)-1,F329) -> 0.033124301 | L329: =L328*(1+E329) -> 102.34763 | M329: =M328*(1+F329) -> 109.36373
...

Sheet Historico_Cota_old
A1: Data | B1: Ibovespa Fechamento | C1: Patrimônio | D1: Cota | E1: Rent - Kairos | F1: Rent - Ibov | G1: Acum - Kairos | H1: Acum - Ibov | I1: MêsAno | J1: Mês - Kairos | K1: Mês - Ibov | L1: Cota 100 - Kairos | M1: Cota 100 - Ibov
A2: 45657 | B2: 120283 | C2: 190188.72 | D2: 1.686855 | E2: -4.2e-05 | F2: 0 | G2: 0 | H2: 0 | I2: =TEXT(A2,"mmaaaa") -> 122024 | J2: 0 | K2: 0 | L2: 100 | M2: 100
A3: 45659 | B3: 120125 | C3: 189667.53 | D3: 1.682233 | E3: -0.00274 | F3: =B3/B2-1 -> -0.0013135688 | G3: =D3/$D$2-1 -> -0.0027400103 | H3: =B3/$B$2-1 -> -0.0013135688 | I3: =TEXT(A3,"mmaaaa") -> 012025 | J3: =E3 -> -0.00274 | K3: =F3 -> -0.0013135688 | L3: =L2*(1+E3) -> 99.726 | M3: =M2*(1+F3) -> 99.868643
A4: 45660 | B4: 118533 | C4: 189169.82 | D4: 1.677818 | E4: -0.002624 | F4: =B4/B3-1 -> -0.013252862 | G4: =D4/$D$2-1 -> -0.0053573069 | H4: =B4/$B$2-1 -> -0.014549022 | I4: =TEXT(A4,"mmaaaa") -> 012025 | J4: =IF(I4=I3,(1+E4)*(1+J3)-1,E4) -> -0.0053568102 | K4: =IF(I4=I3,(1+F4)*(1+K3)-1,F4) -> -0.014549022 | L4: =L3*(1+E4) -> 99.464319 | M4: =M3*(1+F4) -> 98.545098
A5: 45663 | B5: 120022 | C5: 190143.31 | D5: 1.686453 | E5: 0.005147 | F5: =B5/B4-1 -> 0.012561903 | G5: =D5/$D$2-1 -> -0.00023831331 | H5: =B5/$B$2-1 -> -0.0021698827 | I5: =TEXT(A5,"mmaaaa") -> 012025 | J5: =IF(I5=I4,(1+E5)*(1+J4)-1,E5) -> -0.00023738174 | K5: =IF(I5=I4,(1+F5)*(1+K4)-1,F5) -> -0.0021698827 | L5: =L4*(1+E5) -> 99.976262 | M5: =M4*(1+F5) -> 99.783012
A6: 45664 | B6: 121163 | C6: 190298.22 | D6: 1.687827 | E6: 0.000815 | F6: =B6/B5-1 -> 0.0095065905 | G6: =D6/$D$2-1 -> 0.00057622024 | H6: =B6/$B$2-1 -> 0.0073160796 | I6: =TEXT(A6,"mmaaaa") -> 012025 | J6: =IF(I6=I5,(1+E6)*(1+J5)-1,E6) -> 0.00057742479 | K6: =IF(I6=I5,(1+F6)*(1+K5)-1,F6) -> 0.0073160796 | L6: =L5*(1+E6) -> 100.05774 | M6: =M5*(1+F6) -> 100.73161
A7: 45665 | B7: 119625 | C7: 189721.42 | D7: 1.682711 | E7: -0.003031 | F7: =B7/B6-1 -> -0.012693644 | G7: =D7/$D$2-1 -> -0.0024566427 | H7: =B7/$B$2-1 -> -0.0054704322 | I7: =TEXT(A7,"mmaaaa") -> 012025 | J7: =IF(I7=I6,(1+E7)*(1+J6)-1,E7) -> -0.0024553254 | K7: =IF(I7=I6,(1+F7)*(1+K6)-1,F7) -> -0.0054704322 | L7: =L6*(1+E7) -> 99.754467 | M7: =M6*(1+F7) -> 99.452957
A8: 45666 | B8: 119781 | C8: 190414.22 | D8: 1.688855 | E8: 0.003651 | F8: =B8/B7-1 -> 0.0013040752 | G8: =D8/$D$2-1 -> 0.0011856384 | H8: =B8/$B$2-1 -> -0.0041734909 | I8: =TEXT(A8,"mmaaaa") -> 012025 | J8: =IF(I8=I7,(1+E8)*(1+J7)-1,E8) -> 0.0011867102 | K8: =IF(I8=I7,(1+F8)*(1+K7)-1,F8) -> -0.0041734909 | L8: =L7*(1+E8) -> 100.11867 | M8: =M7*(1+F8) -> 99.582651
A9: 45667 | B9: 118856 | C9: 189271.59 | D9: 1.678721 | E9: -0.006001 | F9: =B9/B8-1 -> -0.0077224268 | G9: =D9/$D$2-1 -> -0.0048219912 | H9: =B9/$B$2-1 -> -0.011863688 | I9: =TEXT(A9,"mmaaaa") -> 012025 | J9: =IF(I9=I8,(1+E9)*(1+J8)-1,E9) -> -0.0048214112 | K9: =IF(I9=I8,(1+F9)*(1+K8)-1,F9) -> -0.011863688 | L9: =L8*(1+E9) -> 99.517859 | M9: =M8*(1+F9) -> 98.813631
A10: 45670 | B10: 119007 | C10: 189075.79 | D10: 1.676984 | E10: -0.001035 | F10: =B10/B9-1 -> 0.0012704449 | G10: =D10/$D$2-1 -> -0.0058517181 | H10: =B10/$B$2-1 -> -0.010608315 | I10: =TEXT(A10,"mmaaaa") -> 012025 | J10: =IF(I10=I9,(1+E10)*(1+J9)-1,E10) -> -0.0058514211 | K10: =IF(I10=I9,(1+F10)*(1+K9)-1,F10) -> -0.010608315 | L10: =L9*(1+E10) -> 99.414858 | M10: =M9*(1+F10) -> 98.939168
A11: 45671 | B11: 119299 | C11: 189614.74 | D11: 1.681765 | E11: 0.002851 | F11: =B11/B10-1 -> 0.0024536372 | G11: =D11/$D$2-1 -> -0.0030174496 | H11: =B11/$B$2-1 -> -0.0081807072 | I11: =TEXT(A11,"mmaaaa") -> 012025 | J11: =IF(I11=I10,(1+E11)*(1+J10)-1,E11) -> -0.0030171035 | K11: =IF(I11=I10,(1+F11)*(1+K10)-1,F11) -> -0.0081807072 | L11: =L10*(1+E11) -> 99.69829 | M11: =M10*(1+F11) -> 99.181929
A12: 45672 | B12: 122650 | C12: 193622.13 | D12: 1.717308 | E12: 0.021134 | F12: =B12/B11-1 -> 0.028089087 | G12: =D12/$D$2-1 -> 0.018053123 | H12: =B12/$B$2-1 -> 0.019678591 | I12: =TEXT(A12,"mmaaaa") -> 012025 | J12: =IF(I12=I11,(1+E12)*(1+J11)-1,E12) -> 0.018053133 | K12: =IF(I12=I11,(1+F12)*(1+K11)-1,F12) -> 0.019678591 | L12: =L11*(1+E12) -> 101.80531 | M12: =M11*(1+F12) -> 101.96786
A13: 45673 | B13: 121234 | C13: 192816.65 | D13: 1.710163 | E13: -0.004161 | F13: =B13/B12-1 -> -0.011545047 | G13: =D13/$D$2-1 -> 0.013817429 | H13: =B13/$B$2-1 -> 0.0079063542 | I13: =TEXT(A13,"mmaaaa") -> 012025 | J13: =IF(I13=I12,(1+E13)*(1+J12)-1,E13) -> 0.013817014 | K13: =IF(I13=I12,(1+F13)*(1+K12)-1,F13) -> 0.0079063542 | L13: =L12*(1+E13) -> 101.3817 | M13: =M12*(1+F13) -> 100.79064
A14: 45674 | B14: 122350 | C14: 194729.05 | D14: 1.727125 | E14: 0.009918 | F14: =B14/B13-1 -> 0.0092053384 | G14: =D14/$D$2-1 -> 0.023872828 | H14: =B14/$B$2-1 -> 0.017184473 | I14: =TEXT(A14,"mmaaaa") -> 012025 | J14: =IF(I14=I13,(1+E14)*(1+J13)-1,E14) -> 0.023872051 | K14: =IF(I14=I13,(1+F14)*(1+K13)-1,F14) -> 0.017184473 | L14: =L13*(1+E14) -> 102.38721 | M14: =M13*(1+F14) -> 101.71845
A15: 45677 | B15: 122855 | C15: 194249.17 | D15: 1.722869 | E15: -0.002464 | F15: =B15/B14-1 -> 0.0041275031 | G15: =D15/$D$2-1 -> 0.02134979 | H15: =B15/$B$2-1 -> 0.021382905 | I15: =TEXT(A15,"mmaaaa") -> 012025 | J15: =IF(I15=I14,(1+E15)*(1+J14)-1,E15) -> 0.02134923 | K15: =IF(I15=I14,(1+F15)*(1+K14)-1,F15) -> 0.021382905 | L15: =L14*(1+E15) -> 102.13492 | M15: =M14*(1+F15) -> 102.13829
... A42: 45714 | B42: 124769 | C42: 129655.75 | D42: 1.745655 | E42: 0.000683 | F42: =B42/B41-1 -> -0.0096126369 | G42: =D42/$D$2-1 -> 0.034857768 | H42: =B42/$B$2-1 -> 0.037295378 | I42: =TEXT(A42,"mmaaaa") -> 022025 | J42: =IF(I42=I41,(1+E42)*(1+J41)-1,E42) -> -0.00027183407 | K42: =IF(I42=I41,(1+F42)*(1+K41)-1,F42) -> -0.010829667 | L42: =L41*(1+E42) -> 103.48578 | M42: =M41*(1+F42) -> 103.72954

Sheet Cotistas
A1: Data | B1: CPF | C1: Patrimônio Bruto | D1: (%) | E1: CPF Form
A2: 45688 | B2: 6636857960 | C2: 62830.72 | D2: 0.5377 | E2: =TEXT(B2,"000\.000\.000-00") -> 066.368.579-60
A3: 45688 | B3: 36022818842 | C3: 29252.87 | D3: 0.2503 | E3: =TEXT(B3,"000\.000\.000-00") -> 360.228.188-42
A4: 45688 | B4: 89299655049 | C4: 14760.75 | D4: 0.1263 | E4: =TEXT(B4,"000\.000\.000-00") -> 892.996.550-49
A5: 45688 | B5: 25243679836 | C5: 6053.86 | D5: 0.0518 | E5: =TEXT(B5,"000\.000\.000-00") -> 252.436.798-36
A6: 45688 | B6: 9857890938 | C6: 989.15 | D6: 0.0085 | E6: =TEXT(B6,"000\.000\.000-00") -> 098.578.909-38
A7: 45688 | B7: 4462471970 | C7: 982.36 | D7: 0.0084 | E7: =TEXT(B7,"000\.000\.000-00") -> 044.624.719-70
A8: 45688 | B8: 87256673949 | C8: 959.54 | D8: 0.0082 | E8: =TEXT(B8,"000\.000\.000-00") -> 872.566.739-49
A9: 45688 | B9: 14554897940 | C9: 523.05 | D9: 0.0045 | E9: =TEXT(B9,"000\.000\.000-00") -> 145.548.979-40
A10: 45688 | B10: 9136033928 | C10: 509.43 | D10: 0.0044 | E10: =TEXT(B10,"000\.000\.000-00") -> 091.360.339-28
A11: 45714 | B11: 6636857960 | C11: 62813.6 | D11: 0.4845 | E11: =TEXT(B11,"000\.000\.000-00") -> 066.368.579-60
A12: 45714 | B12: 36022818842 | C12: 39222.77 | D12: 0.3025 | E12: =TEXT(B12,"000\.000\.000-00") -> 360.228.188-42
A13: 45714 | B13: 89299655049 | C13: 14756.73 | D13: 0.1138 | E13: =TEXT(B13,"000\.000\.000-00") -> 892.996.550-49
... A34: 46104 | B34: 87256673949 | C34: 2546.06 | D34: 0.0149 | E34: =TEXT(B34,"000\.000\.000-00") -> 872.566.739-49

Sheet ID Cotistas
A1: NOME COTISTA | B1: ID COTISTA (BRITECH) | C1: CPF
A2: Alex Sandro Dantas da Paixao | B2: 176770 | C2: 25243679836
A3: Andre Otsuka Sato | B3: 176780 | C3: 6636857960
A4: Daniel Soares de Lima | B4: 156844 | C4: 8126566957
A5: Joao Pedro Bassi | B5: 176776 | C5: 14554897940
A6: JOAO PEDRO REZENDE CARPI | B6: 176966 | C6: 43400007870
A7: Lohan Tavares de Lima | B7: 176781 | C7: 9857890938
A8: Maico Felipe Sureck | B8: 176765 | C8: 9136033928
A9: Mateus Muzzillo Coelho | B9: 176794 | C9: 12255597900
A10: Noemia Eri Matsumoto | B10: 176787 | C10: 89299655049
A11: Pablo de Abreu Oliveira | B11: 176786 | C11: 11076050913
A12: Rafael Brandao Souza | B12: 176762 | C12: 36022818842
A13: Silvio Tadeu Sureck | B13: 176769 | C13: 87256673949

Sheet Ativos
A1: Data | B1: Ativo | C1: Vlr Total | D1: % PL | E1: Setor | F1: Categoria | G1: PL | H1: SA | J1: Data | K1: Ativo | L1: Vlr Total | M1: % PL | N1: Setor | O1: Categoria | P1: PL
A2: 45688 | B2: LFT | C2: 15980.99 | D2: =C2/G2 -> 0.13675123 | E2: =_xlfn.XLOOKUP(B2,Cadastro_Acoes!A:A,Cadastro_Acoes!C:C) -> Títulos Públicos | F2: Títulos Públicos | G2: 116861.76 | J2: 45761 | K2: BBAS3 | L2: 14287.63 | M2: 0.12043989 | N2: Intermediários Financeiros | O2: Ações | P2: 118628.72
A3: 45688 | B3: BBAS3 | C3: 13978.4 | D3: =C3/G3 -> 0.11961483 | E3: =_xlfn.XLOOKUP(B3,Cadastro_Acoes!A:A,Cadastro_Acoes!C:C) -> Intermediários Financeiros | F3: Ações | G3: 116861.76 | J3: 45761 | K3: BBSE3 | L3: 7171.62 | M3: 0.060454332 | N3: Previdência e Seguros | O3: Ações | P3: 118628.72
A4: 45688 | B4: BBSE3 | C4: 6397.64 | D4: =C4/G4 -> 0.054745368 | E4: =_xlfn.XLOOKUP(B4,Cadastro_Acoes!A:A,Cadastro_Acoes!C:C) -> Previdência e Seguros | F4: Ações | G4: 116861.76 | J4: 45761 | K4: BPAC11 | L4: 14714.64 | M4: 0.12403944 | N4: Intermediários Financeiros | O4: Ações | P4: 118628.72
A5: 45688 | B5: BPAC11 | C5: 12376.6 | D5: =C5/G5 -> 0.10590804 | E5: =_xlfn.XLOOKUP(B5,Cadastro_Acoes!A:A,Cadastro_Acoes!C:C) -> Intermediários Financeiros | F5: Ações | G5: 116861.76 | J5: 45761 | K5: EGIE3 | L5: 11445.12 | M5: 0.096478492 | N5: Energia Elétrica | O5: Ações | P5: 118628.72
A6: 45688 | B6: EGIE3 | C6: 9200 | D6: =C6/G6 -> 0.078725496 | E6: =_xlfn.XLOOKUP(B6,Cadastro_Acoes!A:A,Cadastro_Acoes!C:C) -> Energia Elétrica | F6: Ações | G6: 116861.76 | J6: 45761 | K6: ELET6 | L6: 15627.08 | M6: 0.131731 | N6: Energia Elétrica | O6: Ações | P6: 118628.72
A7: 45688 | B7: ELET6 | C7: 11830.6 | D7: =C7/G7 -> 0.10123585 | E7: =_xlfn.XLOOKUP(B7,Cadastro_Acoes!A:A,Cadastro_Acoes!C:C) -> Energia Elétrica | F7: Ações | G7: 116861.76 | J7: 45761 | K7: IVVB11 | L7: 6734.55 | M7: 0.056769979 | N7: Fundos de índice | O7: Ações | P7: 118628.72
A8: 45688 | B8: IVVB11 | C8: 8671.3 | D8: =C8/G8 -> 0.074201347 | E8: =_xlfn.XLOOKUP(B8,Cadastro_Acoes!A:A,Cadastro_Acoes!C:C) -> Fundos de índice | F8: Ações | G8: 116861.76 | J8: 45761 | K8: PRIO3 | L8: 14272.04 | M8: 0.12030847 | N8: Petróleo, Gás e Biocombustíveis | O8: Ações | P8: 118628.72
A9: 45688 | B9: PRIO3 | C9: 11190.27 | D9: =C9/G9 -> 0.095756473 | E9: =_xlfn.XLOOKUP(B9,Cadastro_Acoes!A:A,Cadastro_Acoes!C:C) -> Petróleo, Gás e Biocombustíveis | F9: Ações | G9: 116861.76 | J9: 45761 | K9: USTK11 | L9: 6237.81 | M9: 0.052582629 | N9: Fundos de índice | O9: Ações | P9: 118628.72
A10: 45688 | B10: USTK11 | C10: 11347 | D10: =C10/G10 -> 0.097097631 | E10: =_xlfn.XLOOKUP(B10,Cadastro_Acoes!A:A,Cadastro_Acoes!C:C) -> Fundos de índice | F10: Ações | G10: 116861.76 | J10: 45761 | K10: VALE3 | L10: 13861.8 | M10: 0.11685029 | N10: Mineração | O10: Ações | P10: 118628.72
A11: 45688 | B11: VALE3 | C11: 12079.91 | D11: =C11/G11 -> 0.10336923 | E11: =_xlfn.XLOOKUP(B11,Cadastro_Acoes!A:A,Cadastro_Acoes!C:C) -> Mineração | F11: Ações | G11: 116861.76 | J11: 45761 | K11: CAIXA | L11: 13668.29 | M11: 0.11521906 | N11: Caixa | O11: Caixa | P11: 118628.72
A12: 45688 | B12: CAIXA | C12: 2784.12 | D12: =C12/G12 -> 0.023824046 | E12: =_xlfn.XLOOKUP(B12,Cadastro_Acoes!A:A,Cadastro_Acoes!C:C) -> Caixa | F12: Caixa | G12: 116861.76
A13: 45716 | B13: LFT | C13: 16138.49 | D13: =C13/G13 -> 0.12480968 | E13: =_xlfn.XLOOKUP(B13,Cadastro_Acoes!A:A,Cadastro_Acoes!C:C) -> Títulos Públicos | F13: Títulos Públicos | G13: 129304.79
A14: 45716 | B14: BBAS3 | C14: 13900.79 | D14: =C14/G14 -> 0.10750406 | E14: =_xlfn.XLOOKUP(B14,Cadastro_Acoes!A:A,Cadastro_Acoes!C:C) -> Intermediários Financeiros | F14: Ações | G14: 129304.79
A15: 45716 | B15: BBSE3 | C15: 6735.52 | D15: =C15/G15 -> 0.052090259 | E15: =_xlfn.XLOOKUP(B15,Cadastro_Acoes!A:A,Cadastro_Acoes!C:C) -> Previdência e Seguros | F15: Ações | G15: 129304.79
A16: 45716 | B16: BPAC11 | C16: 13516.24 | D16: =C16/G16 -> 0.10453008 | E16: =_xlfn.XLOOKUP(B16,Cadastro_Acoes!A:A,Cadastro_Acoes!C:C) -> Intermediários Financeiros | F16: Ações | G16: 129304.79
A17: 45716 | B17: EGIE3 | C17: 10704.96 | D17: =C17/G17 -> 0.08278858 | E17: =_xlfn.XLOOKUP(B17,Cadastro_Acoes!A:A,Cadastro_Acoes!C:C) -> Energia Elétrica | F17: Ações | G17: 129304.79
A18: 45716 | B18: ELET6 | C18: 14395.71 | D18: =C18/G18 -> 0.11133161 | E18: =_xlfn.XLOOKUP(B18,Cadastro_Acoes!A:A,Cadastro_Acoes!C:C) -> Energia Elétrica | F18: Ações | G18: 129304.79
A19: 45716 | B19: IVVB11 | C19: 10210.2 | D19: =C19/G19 -> 0.078962272 | E19: =_xlfn.XLOOKUP(B19,Cadastro_Acoes!A:A,Cadastro_Acoes!C:C) -> Fundos de índice | F19: Ações | G19: 129304.79
A20: 45716 | B20: PRIO3 | C20: 12290.74 | D20: =C20/G20 -> 0.095052473 | E20: =_xlfn.XLOOKUP(B20,Cadastro_Acoes!A:A,Cadastro_Acoes!C:C) -> Petróleo, Gás e Biocombustíveis | F20: Ações | G20: 129304.79
A21: 45716 | B21: USTK11 | C21: 11123 | D21: =C21/G21 -> 0.086021562 | E21: =_xlfn.XLOOKUP(B21,Cadastro_Acoes!A:A,Cadastro_Acoes!C:C) -> Fundos de índice | F21: Ações | G21: 129304.79
A22: 45716 | B22: VALE3 | C22: 14063.25 | D22: =C22/G22 -> 0.10876047 | E22: =_xlfn.XLOOKUP(B22,Cadastro_Acoes!A:A,Cadastro_Acoes!C:C) -> Mineração | F22: Ações | G22: 129304.79
A23: 45716 | B23: CAIXA | C23: 5106.51 | D23: =C23/G23 -> 0.03949204 | E23: =_xlfn.XLOOKUP(B23,Cadastro_Acoes!A:A,Cadastro_Acoes!C:C) -> Caixa | F23: Caixa | G23: 129304.79
... A34: 45723 | B34: CAIXA | C34: 5320.45 | D34: =C34/G34 -> 0.040949568 | E34: =_xlfn.XLOOKUP(B34,Cadastro_Acoes!A:A,Cadastro_Acoes!C:C) -> Caixa | F34: Caixa | G34: 129926.89
A35: 45730 | B35: LFT | C35: 16201.76 | D35: =C35/G35 -> 0.12315543 | E35: =_xlfn.XLOOKUP(B35,Cadastro_Acoes!A:A,Cadastro_Acoes!C:C) -> Títulos Públicos | F35: Títulos Públicos | G35: =_xlfn.XLOOKUP(A35,Historico_Cota!A:A,Historico_Cota!C:C) -> 131555.39
A36: 45730 | B36: BBAS3 | C36: 14190.92 | D36: =C36/G36 -> 0.1078703 | E36: =_xlfn.XLOOKUP(B36,Cadastro_Acoes!A:A,Cadastro_Acoes!C:C) -> Intermediários Financeiros | F36: Ações | G36: =_xlfn.XLOOKUP(A36,Historico_Cota!A:A,Historico_Cota!C:C) -> 131555.39
A37: 45730 | B37: BBSE3 | C37: 7086.18 | D37: =C37/G37 -> 0.053864612 | E37: =_xlfn.XLOOKUP(B37,Cadastro_Acoes!A:A,Cadastro_Acoes!C:C) -> Previdência e Seguros | F37: Ações | G37: =_xlfn.XLOOKUP(A37,Historico_Cota!A:A,Historico_Cota!C:C) -> 131555.39
A38: 45730 | B38: BPAC11 | C38: 14526.32 | D38: =C38/G38 -> 0.1104198 | E38: =_xlfn.XLOOKUP(B38,Cadastro_Acoes!A:A,Cadastro_Acoes!C:C) -> Intermediários Financeiros | F38: Ações | G38: =_xlfn.XLOOKUP(A38,Historico_Cota!A:A,Historico_Cota!C:C) -> 131555.39
A39: 45730 | B39: EGIE3 | C39: 10877.76 | D39: =C39/G39 -> 0.08268578 | E39: =_xlfn.XLOOKUP(B39,Cadastro_Acoes!A:A,Cadastro_Acoes!C:C) -> Energia Elétrica | F39: Ações | G39: =_xlfn.XLOOKUP(A39,Historico_Cota!A:A,Historico_Cota!C:C) -> 131555.39
A40: 45730 | B40: ELET6 | C40: 15043.98 | D40: =C40/G40 -> 0.11435472 | E40: =_xlfn.XLOOKUP(B40,Cadastro_Acoes!A:A,Cadastro_Acoes!C:C) -> Energia Elétrica | F40: Ações | G40: =_xlfn.XLOOKUP(A40,Historico_Cota!A:A,Historico_Cota!C:C) -> 131555.39
A41: 45730 | B41: IVVB11 | C41: 9412 | D41: =C41/G41 -> 0.071544009 | E41: =_xlfn.XLOOKUP(B41,Cadastro_Acoes!A:A,Cadastro_Acoes!C:C) -> Fundos de índice | F41: Ações | G41: =_xlfn.XLOOKUP(A41,Historico_Cota!A:A,Historico_Cota!C:C) -> 131555.39
A42: 45730 | B42: PRIO3 | C42: 12670.7 | D42: =C42/G42 -> 0.096314564 | E42: =_xlfn.XLOOKUP(B42,Cadastro_Acoes!A:A,Cadastro_Acoes!C:C) -> Petróleo, Gás e Biocombustíveis | F42: Ações | G42: =_xlfn.XLOOKUP(A42,Historico_Cota!A:A,Historico_Cota!C:C) -> 131555.39
A43: 45730 | B43: USTK11 | C43: 10178 | D43: =C43/G43 -> 0.077366651 | E43: =_xlfn.XLOOKUP(B43,Cadastro_Acoes!A:A,Cadastro_Acoes!C:C) -> Fundos de índice | F43: Ações | G43: =_xlfn.XLOOKUP(A43,Historico_Cota!A:A,Historico_Cota!C:C) -> 131555.39
A44: 45730 | B44: VALE3 | C44: 14353.95 | D44: =C44/G44 -> 0.10910955 | E44: =_xlfn.XLOOKUP(B44,Cadastro_Acoes!A:A,Cadastro_Acoes!C:C) -> Mineração | F44: Ações | G44: =_xlfn.XLOOKUP(A44,Historico_Cota!A:A,Historico_Cota!C:C) -> 131555.39
A45: 45730 | B45: CAIXA | C45: 6065.46 | D45: =C45/G45 -> 0.046105751 | E45: =_xlfn.XLOOKUP(B45,Cadastro_Acoes!A:A,Cadastro_Acoes!C:C) -> Caixa | F45: Caixa | G45: =_xlfn.XLOOKUP(A45,Historico_Cota!A:A,Historico_Cota!C:C) -> 131555.39
A46: 45733 | B46: LFT | C46: 16209.74 | D46: =C46/G46 -> 0.1219091 | E46: =_xlfn.XLOOKUP(B46,Cadastro_Acoes!A:A,Cadastro_Acoes!C:C) -> Títulos Públicos | F46: Títulos Públicos | G46: =_xlfn.XLOOKUP(A46,Historico_Cota!A:A,Historico_Cota!C:C) -> 132965.79
... A187: 46104 | B187: EGIE3 | C187: 12243.1 | D187: =C187/G187 -> 0.07153561 | E187: =_xlfn.XLOOKUP(B187,Cadastro_Acoes!A:A,Cadastro_Acoes!C:C) -> Energia Elétrica | F187: Ações | G187: =_xlfn.XLOOKUP(A187,Historico_Cota!A:A,Historico_Cota!C:C) -> 171146.93
A188: 46104 | B188: AXIA6 | C188: =12068.8+2768.5 -> 14837.3 | D188: =C188/G188 -> 0.086693346 | E188: =_xlfn.XLOOKUP(B188,Cadastro_Acoes!A:A,Cadastro_Acoes!C:C) -> Energia Elétrica | F188: Ações | G188: =_xlfn.XLOOKUP(A188,Historico_Cota!A:A,Historico_Cota!C:C) -> 171146.93
A189: 46104 | B189: IVVB11 | C189: 5820 | D189: =C189/G189 -> 0.034005869 | E189: =_xlfn.XLOOKUP(B189,Cadastro_Acoes!A:A,Cadastro_Acoes!C:C) -> Fundos de índice | F189: Ações | G189: =_xlfn.XLOOKUP(A189,Historico_Cota!A:A,Historico_Cota!C:C) -> 171146.93
A190: 46104 | B190: SHUL4 | C190: 10500 | D190: =C190/G190 -> 0.061350794 | E190: =_xlfn.XLOOKUP(B190,Cadastro_Acoes!A:A,Cadastro_Acoes!C:C) -> Bens Industriais | F190: Ações | G190: =_xlfn.XLOOKUP(A190,Historico_Cota!A:A,Historico_Cota!C:C) -> 171146.93
...

Sheet Movimentos
A1: Data | B1: Ativo | C1: Vlr Total | D1: % PL | E1: Setor | F1: Categoria | G1: PL | H1: QTDE | I1: PU | J1: NOVO % PL | K1: NOVA QTDE | L1: MOV | P1: Setor | Q1: SldAnt | R1: SldAtu
A2: 45798 | B2: BBAS3 | C2: 12857.34 | D2: =C2/G2 -> 0.10435305 | E2: =_xlfn.XLOOKUP(B2,Cadastro_Acoes!A:A,Cadastro_Acoes!C:C) -> Intermediários Financeiros | F2: Ações | G2: =_xlfn.XLOOKUP(A2,Historico_Cota!A:A,Historico_Cota!C:C) -> 123210.01 | H2: 509 | I2: =C2/H2 -> 25.26 | J2: 0.115 | K2: =G2*J2/I2 -> 560.93235 | L2: =K2-H2 -> 51.93235 | M2: =J2*G2 -> 14169.151 | N2: =J2*D2 -> 0.0120006 | O2: =N2*D2 -> 0.0012522992 | P2: {=_xlfn.UNIQUE(E2:E11)} -> Intermediários Financeiros | Q2: {=SUMIF(E:E,_xlfn.ANCHORARRAY(P2),C:C)} -> 29780.46 | R2: {=SUMIF(E:E,_xlfn.ANCHORARRAY(P2),M:M)} -> 27722.252
A3: 45798 | B3: BBSE3 | C3: 6783.58 | D3: =C3/G3 -> 0.055057053 | E3: =_xlfn.XLOOKUP(B3,Cadastro_Acoes!A:A,Cadastro_Acoes!C:C) -> Previdência e Seguros | F3: Ações | G3: =_xlfn.XLOOKUP(A3,Historico_Cota!A:A,Historico_Cota!C:C) -> 123210.01 | H3: 178 | I3: =C3/H3 -> 38.11 | J3: 0.05 | K3: =G3*J3/I3 -> 161.6505 | L3: =K3-H3 -> -16.349501 | M3: =J3*G3 -> 6160.5005 | N3: =J3*D3 -> 0.0027528526 | P3: Previdência e Seguros | Q3: 6783.58 | R3: 6160.5005
A4: 45798 | B4: BPAC11 | C4: 16923.12 | D4: =C4/G4 -> 0.13735183 | E4: =_xlfn.XLOOKUP(B4,Cadastro_Acoes!A:A,Cadastro_Acoes!C:C) -> Intermediários Financeiros | F4: Ações | G4: =_xlfn.XLOOKUP(A4,Historico_Cota!A:A,Historico_Cota!C:C) -> 123210.01 | H4: 428 | I4: =C4/H4 -> 39.54 | J4: 0.11 | K4: =G4*J4/I4 -> 342.76938 | L4: =K4-H4 -> -85.230625 | M4: =J4*G4 -> 13553.101 | N4: =J4*D4 -> 0.015108701 | P4: Energia Elétrica | Q4: 27655.83 | R4: 29570.402
A5: 45798 | B5: EGIE3 | C5: 11819.52 | D5: =C5/G5 -> 0.095929868 | E5: =_xlfn.XLOOKUP(B5,Cadastro_Acoes!A:A,Cadastro_Acoes!C:C) -> Energia Elétrica | F5: Ações | G5: =_xlfn.XLOOKUP(A5,Historico_Cota!A:A,Historico_Cota!C:C) -> 123210.01 | H5: 288 | I5: =C5/H5 -> 41.04 | J5: 0.07 | K5: =G5*J5/I5 -> 210.15353 | L5: =K5-H5 -> -77.846474 | M5: =J5*G5 -> 8624.7007 | N5: =J5*D5 -> 0.0067150908 | P5: Fundos de índice | Q5: 13948.04 | R5: 11088.901
A6: 45798 | B6: ELET6 | C6: 15836.31 | D6: =C6/G6 -> 0.12853103 | E6: =_xlfn.XLOOKUP(B6,Cadastro_Acoes!A:A,Cadastro_Acoes!C:C) -> Energia Elétrica | F6: Ações | G6: =_xlfn.XLOOKUP(A6,Historico_Cota!A:A,Historico_Cota!C:C) -> 123210.01 | H6: 343 | I6: =C6/H6 -> 46.17 | J6: 0.07 | K6: =G6*J6/I6 -> 186.80313 | L6: =K6-H6 -> -156.19687 | M6: =J6*G6 -> 8624.7007 | N6: =J6*D6 -> 0.0089971724 | P6: Petróleo, Gás e Biocombustíveis | Q6: 16774.5 | R6: 14785.201
A7: 45798 | B7: IVVB11 | C7: 7026.2 | D7: =C7/G7 -> 0.057026211 | E7: =_xlfn.XLOOKUP(B7,Cadastro_Acoes!A:A,Cadastro_Acoes!C:C) -> Fundos de índice | F7: Ações | G7: =_xlfn.XLOOKUP(A7,Historico_Cota!A:A,Historico_Cota!C:C) -> 123210.01 | H7: 19 | I7: =C7/H7 -> 369.8 | J7: 0.045 | K7: =G7*J7/I7 -> 14.993106 | L7: =K7-H7 -> -4.0068944 | M7: =J7*G7 -> 5544.4504 | N7: =J7*D7 -> 0.0025661795 | P7: Mineração | Q7: 13933.2 | R7: 14169.151
A8: 45798 | B8: PRIO3 | C8: 16774.5 | D8: =C8/G8 -> 0.13614559 | E8: =_xlfn.XLOOKUP(B8,Cadastro_Acoes!A:A,Cadastro_Acoes!C:C) -> Petróleo, Gás e Biocombustíveis | F8: Ações | G8: =_xlfn.XLOOKUP(A8,Historico_Cota!A:A,Historico_Cota!C:C) -> 123210.01 | H8: 422 | I8: =C8/H8 -> 39.75 | J8: 0.12 | K8: =G8*J8/I8 -> 371.95475 | L8: =K8-H8 -> -50.045253 | M8: =J8*G8 -> 14785.201 | N8: =J8*D8 -> 0.016337471
A9: 45798 | B9: USTK11 | C9: 6921.84 | D9: =C9/G9 -> 0.056179202 | E9: =_xlfn.XLOOKUP(B9,Cadastro_Acoes!A:A,Cadastro_Acoes!C:C) -> Fundos de índice | F9: Ações | G9: =_xlfn.XLOOKUP(A9,Historico_Cota!A:A,Historico_Cota!C:C) -> 123210.01 | H9: 453 | I9: =C9/H9 -> 15.28 | J9: 0.045 | K9: =G9*J9/I9 -> 362.8567 | L9: =K9-H9 -> -90.143295 | M9: =J9*G9 -> 5544.4504 | N9: =J9*D9 -> 0.0025280641
A10: 45798 | B10: VALE3 | C10: 13933.2 | D10: =C10/G10 -> 0.11308497 | E10: =_xlfn.XLOOKUP(B10,Cadastro_Acoes!A:A,Cadastro_Acoes!C:C) -> Mineração | F10: Ações | G10: =_xlfn.XLOOKUP(A10,Historico_Cota!A:A,Historico_Cota!C:C) -> 123210.01 | H10: 255 | I10: =C10/H10 -> 54.64 | J10: 0.115 | K10: =G10*J10/I10 -> 259.31829 | L10: =K10-H10 -> 4.3182861 | M10: =J10*G10 -> 14169.151 | N10: =J10*D10 -> 0.013004771
A11: 45798 | B11: AURE3 | C11: 0 | D11: =C11/G11 -> 0 | E11: =_xlfn.XLOOKUP(B11,Cadastro_Acoes!A:A,Cadastro_Acoes!C:C) -> Energia Elétrica | F11: Ações | G11: =_xlfn.XLOOKUP(A11,Historico_Cota!A:A,Historico_Cota!C:C) -> 123210.01 | H11: 0 | I11: 9.39 | J11: 0.1 | K11: =G11*J11/I11 -> 1312.1407 | L11: =K11-H11 -> 1312.1407 | M11: =J11*G11 -> 12321.001 | N11: =J11*D11 -> 0
A12: 45798 | B12: CAIXA | C12: 13513.32 | D12: =C12/G12 -> 0.10967713 | E12: =_xlfn.XLOOKUP(B12,Cadastro_Acoes!A:A,Cadastro_Acoes!C:C) -> Caixa | F12: Caixa | G12: =_xlfn.XLOOKUP(A12,Historico_Cota!A:A,Historico_Cota!C:C) -> 123210.01 | H12: - | I12: - | J12: =SUM(J2:J11) -> 0.84
D13: =SUM(D2:D10) -> 0.8836588

Sheet Rent_Mensal
B2: 45292 | C2: =EOMONTH(B2,0+1) -> 45351 | D2: =EOMONTH(C2,0+1) -> 45382 | E2: =EOMONTH(D2,0+1) -> 45412 | F2: =EOMONTH(E2,0+1) -> 45443 | G2: =EOMONTH(F2,0+1) -> 45473 | H2: =EOMONTH(G2,0+1) -> 45504 | I2: =EOMONTH(H2,0+1) -> 45535 | J2: =EOMONTH(I2,0+1) -> 45565 | ... M2: =EOMONTH(L2,0+1) -> 45657
B3: =TEXT(B2,"mmaaaa") -> 012024 | C3: =TEXT(C2,"mmaaaa") -> 022024 | D3: =TEXT(D2,"mmaaaa") -> 032024 | E3: =TEXT(E2,"mmaaaa") -> 042024 | F3: =TEXT(F2,"mmaaaa") -> 052024 | G3: =TEXT(G2,"mmaaaa") -> 062024 | H3: =TEXT(H2,"mmaaaa") -> 072024 | I3: =TEXT(I2,"mmaaaa") -> 082024 | ... M3: =TEXT(M2,"mmaaaa") -> 122024
B5: 45658 | C5: =EOMONTH(B5,0+1) -> 45716 | D5: =EOMONTH(C5,0+1) -> 45747 | E5: =EOMONTH(D5,0+1) -> 45777 | F5: =EOMONTH(E5,0+1) -> 45808 | G5: =EOMONTH(F5,0+1) -> 45838 | H5: =EOMONTH(G5,0+1) -> 45869 | I5: =EOMONTH(H5,0+1) -> 45900 | J5: =EOMONTH(I5,0+1) -> 45930 | ... M5: =EOMONTH(L5,0+1) -> 46022
B6: =TEXT(B5,"mmaaaa") -> 012025 | C6: =TEXT(C5,"mmaaaa") -> 022025 | D6: =TEXT(D5,"mmaaaa") -> 032025 | E6: =TEXT(E5,"mmaaaa") -> 042025 | F6: =TEXT(F5,"mmaaaa") -> 052025 | G6: =TEXT(G5,"mmaaaa") -> 062025 | H6: =TEXT(H5,"mmaaaa") -> 072025 | I6: =TEXT(I5,"mmaaaa") -> 082025 | ... M6: =TEXT(M5,"mmaaaa") -> 122025
B8: 46023 | C8: =EOMONTH(B8,0+1) -> 46081 | D8: =EOMONTH(C8,0+1) -> 46112 | E8: =EOMONTH(D8,0+1) -> 46142 | F8: =EOMONTH(E8,0+1) -> 46173 | G8: =EOMONTH(F8,0+1) -> 46203 | H8: =EOMONTH(G8,0+1) -> 46234 | I8: =EOMONTH(H8,0+1) -> 46265 | J8: =EOMONTH(I8,0+1) -> 46295 | ... M8: =EOMONTH(L8,0+1) -> 46387
B9: =TEXT(B8,"mmaaaa") -> 012026 | C9: =TEXT(C8,"mmaaaa") -> 022026 | D9: =TEXT(D8,"mmaaaa") -> 032026 | E9: =TEXT(E8,"mmaaaa") -> 042026 | F9: =TEXT(F8,"mmaaaa") -> 052026 | G9: =TEXT(G8,"mmaaaa") -> 062026 | H9: =TEXT(H8,"mmaaaa") -> 072026 | I9: =TEXT(I8,"mmaaaa") -> 082026 | ... M9: =TEXT(M8,"mmaaaa") -> 122026
A10: Ano | B10: =PROPER(TEXT(B5,"mmm")) -> Jan | C10: =PROPER(TEXT(C5,"mmm")) -> Fev | D10: =PROPER(TEXT(D5,"mmm")) -> Mar | E10: =PROPER(TEXT(E5,"mmm")) -> Abr | F10: =PROPER(TEXT(F5,"mmm")) -> Mai | G10: =PROPER(TEXT(G5,"mmm")) -> Jun | H10: =PROPER(TEXT(H5,"mmm")) -> Jul | I10: =PROPER(TEXT(I5,"mmm")) -> Ago | ... M10: =PROPER(TEXT(M5,"mmm")) -> Dez | N10: Total
A11: 2026 - Kairos | B11: =_xlfn.XLOOKUP(B9,Historico_Cota!$I:$I,Historico_Cota!$J:$J,"-",,-1) -> 0.080273778 | C11: =_xlfn.XLOOKUP(C9,Historico_Cota!$I:$I,Historico_Cota!$J:$J,"-",,-1) -> 0.042696053 | D11: =_xlfn.XLOOKUP(D9,Historico_Cota!$I:$I,Historico_Cota!$J:$J,"-",,-1) -> -0.023829708 | E11: =_xlfn.XLOOKUP(E9,Historico_Cota!$I:$I,Historico_Cota!$J:$J,"-",,-1) -> - | F11: =_xlfn.XLOOKUP(F9,Historico_Cota!$I:$I,Historico_Cota!$J:$J,"-",,-1) -> - | G11: =_xlfn.XLOOKUP(G9,Historico_Cota!$I:$I,Historico_Cota!$J:$J,"-",,-1) -> - | H11: =_xlfn.XLOOKUP(H9,Historico_Cota!$I:$I,Historico_Cota!$J:$J,"-",,-1) -> - | I11: =_xlfn.XLOOKUP(I9,Historico_Cota!$I:$I,Historico_Cota!$J:$J,"-",,-1) -> - | ... M11: =_xlfn.XLOOKUP(M9,Historico_Cota!$I:$I,Historico_Cota!$J:$J,"-",,-1) -> - | N11: {=EXP(SUM(LN(1+_xlfn._xlws.FILTER(B11:M11,B11:M11<>"-"))))-1} -> 0.099555488
A12: 2026 - Ibov | B12: =_xlfn.XLOOKUP(B9,Historico_Cota!$I:$I,Historico_Cota!$K:$K,"-",,-1) -> 0.12560735 | C12: =_xlfn.XLOOKUP(C9,Historico_Cota!$I:$I,Historico_Cota!$K:$K,"-",,-1) -> 0.040929204 | D12: =_xlfn.XLOOKUP(D9,Historico_Cota!$I:$I,Historico_Cota!$K:$K,"-",,-1) -> -0.036311032 | E12: =_xlfn.XLOOKUP(E9,Historico_Cota!$I:$I,Historico_Cota!$K:$K,"-",,-1) -> - | F12: =_xlfn.XLOOKUP(F9,Historico_Cota!$I:$I,Historico_Cota!$K:$K,"-",,-1) -> - | G12: =_xlfn.XLOOKUP(G9,Historico_Cota!$I:$I,Historico_Cota!$K:$K,"-",,-1) -> - | H12: =_xlfn.XLOOKUP(H9,Historico_Cota!$I:$I,Historico_Cota!$K:$K,"-",,-1) -> - | I12: =_xlfn.XLOOKUP(I9,Historico_Cota!$I:$I,Historico_Cota!$K:$K,"-",,-1) -> - | ... M12: =_xlfn.XLOOKUP(M9,Historico_Cota!$I:$I,Historico_Cota!$K:$K,"-",,-1) -> - | N12: {=EXP(SUM(LN(1+_xlfn._xlws.FILTER(B12:M12,B12:M12<>"-"))))-1} -> 0.12913274
A13: % Ibov | B13: =IFERROR((1+B11)/(1+B12),"-") -> 0.95972524 | C13: =IFERROR((1+C11)/(1+C12),"-") -> 1.0016974 | D13: =IFERROR((1+D11)/(1+D12),"-") -> 1.0129516 | E13: =IFERROR((1+E11)/(1+E12),"-") -> - | F13: =IFERROR((1+F11)/(1+F12),"-") -> - | G13: =IFERROR((1+G11)/(1+G12),"-") -> - | H13: =IFERROR((1+H11)/(1+H12),"-") -> - | I13: =IFERROR((1+I11)/(1+I12),"-") -> - | ... N13: =IFERROR((1+N11)/(1+N12),"-") -> 0.97380534
A14: 2025 - Kairos | B14: =_xlfn.XLOOKUP(B6,Historico_Cota!$I:$I,Historico_Cota!$J:$J,"-",,-1) -> 0.03513995 | C14: =_xlfn.XLOOKUP(C6,Historico_Cota!$I:$I,Historico_Cota!$J:$J,"-",,-1) -> -0.0029785852 | D14: =_xlfn.XLOOKUP(D6,Historico_Cota!$I:$I,Historico_Cota!$J:$J,"-",,-1) -> 0.021304705 | E14: =_xlfn.XLOOKUP(E6,Historico_Cota!$I:$I,Historico_Cota!$J:$J,"-",,-1) -> 0.013270379 | F14: =_xlfn.XLOOKUP(F6,Historico_Cota!$I:$I,Historico_Cota!$J:$J,"-",,-1) -> -0.0012932841 | G14: =_xlfn.XLOOKUP(G6,Historico_Cota!$I:$I,Historico_Cota!$J:$J,"-",,-1) -> 0.017282421 | H14: =_xlfn.XLOOKUP(H6,Historico_Cota!$I:$I,Historico_Cota!$J:$J,"-",,-1) -> -0.043065351 | I14: =_xlfn.XLOOKUP(I6,Historico_Cota!$I:$I,Historico_Cota!$J:$J,"-",,-1) -> 0.045104333 | ... M14: =_xlfn.XLOOKUP(M6,Historico_Cota!$I:$I,Historico_Cota!$J:$J,"-",,-1) -> 0.033009211 | N14: {=EXP(SUM(LN(1+_xlfn._xlws.FILTER(B14:M14,B14:M14<>"-"))))-1} -> 0.24289692
A15: 2025 - Ibov | B15: =_xlfn.XLOOKUP(B6,Historico_Cota!$I:$I,Historico_Cota!$K:$K,"-",,-1) -> 0.048651929 | C15: =_xlfn.XLOOKUP(C6,Historico_Cota!$I:$I,Historico_Cota!$K:$K,"-",,-1) -> -0.026447853 | D15: =_xlfn.XLOOKUP(D6,Historico_Cota!$I:$I,Historico_Cota!$K:$K,"-",,-1) -> 0.060757824 | E15: =_xlfn.XLOOKUP(E6,Historico_Cota!$I:$I,Historico_Cota!$K:$K,"-",,-1) -> 0.036903117 | F15: =_xlfn.XLOOKUP(F6,Historico_Cota!$I:$I,Historico_Cota!$K:$K,"-",,-1) -> 0.014511317 | G15: =_xlfn.XLOOKUP(G6,Historico_Cota!$I:$I,Historico_Cota!$K:$K,"-",,-1) -> 0.013340437 | H15: =_xlfn.XLOOKUP(H6,Historico_Cota!$I:$I,Historico_Cota!$K:$K,"-",,-1) -> -0.041654604 | I15: =_xlfn.XLOOKUP(I6,Historico_Cota!$I:$I,Historico_Cota!$K:$K,"-",,-1) -> 0.062757527 | ... M15: =_xlfn.XLOOKUP(M6,Historico_Cota!$I:$I,Historico_Cota!$K:$K,"-",,-1) -> 0.012907604 | N15: {=EXP(SUM(LN(1+_xlfn._xlws.FILTER(B15:M15,B15:M15<>"-"))))-1} -> 0.33955231
A16: % Ibov | B16: =IFERROR((1+B14)/(1+B15),"-") -> 0.98711491 | C16: =IFERROR((1+C14)/(1+C15),"-") -> 1.0241068 | D16: =IFERROR((1+D14)/(1+D15),"-") -> 0.96280667 | E16: =IFERROR((1+E14)/(1+E15),"-") -> 0.97720835 | F16: =IFERROR((1+F14)/(1+F15),"-") -> 0.98442146 | G16: =IFERROR((1+G14)/(1+G15),"-") -> 1.0038901 | H16: =IFERROR((1+H14)/(1+H15),"-") -> 0.99852793 | I16: =IFERROR((1+I14)/(1+I15),"-") -> 0.98338926 | ... N16: =IFERROR((1+N14)/(1+N15),"-") -> 0.92784501
A17: 2024 - Kairos | B17: =_xlfn.XLOOKUP(B3,Historico_Cota!$I:$I,Historico_Cota!$J:$J,"-",,-1) -> - | C17: =_xlfn.XLOOKUP(C3,Historico_Cota!$I:$I,Historico_Cota!$J:$J,"-",,-1) -> 0.014395461 | D17: =_xlfn.XLOOKUP(D3,Historico_Cota!$I:$I,Historico_Cota!$J:$J,"-",,-1) -> -0.011765048 | E17: =_xlfn.XLOOKUP(E3,Historico_Cota!$I:$I,Historico_Cota!$J:$J,"-",,-1) -> -0.031615861 | F17: =_xlfn.XLOOKUP(F3,Historico_Cota!$I:$I,Historico_Cota!$J:$J,"-",,-1) -> -0.023466203 | G17: =_xlfn.XLOOKUP(G3,Historico_Cota!$I:$I,Historico_Cota!$J:$J,"-",,-1) -> 0.0059574784 | H17: =_xlfn.XLOOKUP(H3,Historico_Cota!$I:$I,Historico_Cota!$J:$J,"-",,-1) -> 0.042014473 | I17: =_xlfn.XLOOKUP(I3,Historico_Cota!$I:$I,Historico_Cota!$J:$J,"-",,-1) -> 0.040594101 | ... M17: =_xlfn.XLOOKUP(M3,Historico_Cota!$I:$I,Historico_Cota!$J:$J,"-",,-1) -> -0.011377039 | N17: {=EXP(SUM(LN(1+_xlfn._xlws.FILTER(B17:M17,B17:M17<>"-"))))-1} -> -0.055558493
A18: 2024 - Ibov | B18: =_xlfn.XLOOKUP(B3,Historico_Cota!$I:$I,Historico_Cota!$K:$K,"-",,-1) -> - | C18: =_xlfn.XLOOKUP(C3,Historico_Cota!$I:$I,Historico_Cota!$K:$K,"-",,-1) -> 0.011180273 | D18: =_xlfn.XLOOKUP(D3,Historico_Cota!$I:$I,Historico_Cota!$K:$K,"-",,-1) -> -0.0070835518 | E18: =_xlfn.XLOOKUP(E3,Historico_Cota!$I:$I,Historico_Cota!$K:$K,"-",,-1) -> -0.017032054 | F18: =_xlfn.XLOOKUP(F3,Historico_Cota!$I:$I,Historico_Cota!$K:$K,"-",,-1) -> -0.030384154 | G18: =_xlfn.XLOOKUP(G3,Historico_Cota!$I:$I,Historico_Cota!$K:$K,"-",,-1) -> 0.014811534 | H18: =_xlfn.XLOOKUP(H3,Historico_Cota!$I:$I,Historico_Cota!$K:$K,"-",,-1) -> 0.030226489 | I18: =_xlfn.XLOOKUP(I3,Historico_Cota!$I:$I,Historico_Cota!$K:$K,"-",,-1) -> 0.065429546 | ... M18: =_xlfn.XLOOKUP(M3,Historico_Cota!$I:$I,Historico_Cota!$K:$K,"-",,-1) -> -0.042849709 | N18: {=EXP(SUM(LN(1+_xlfn._xlws.FILTER(B18:M18,B18:M18<>"-"))))-1} -> -0.057295165
A19: % Ibov | B19: =IFERROR((1+B17)/(1+B18),"-") -> - | C19: =IFERROR((1+C17)/(1+C18),"-") -> 1.0031796 | D19: =IFERROR((1+D17)/(1+D18),"-") -> 0.99528511 | E19: =IFERROR((1+E17)/(1+E18),"-") -> 0.9851635 | F19: =IFERROR((1+F17)/(1+F18),"-") -> 1.0071347 | G19: =IFERROR((1+G17)/(1+G18),"-") -> 0.99127517 | H19: =IFERROR((1+H17)/(1+H18),"-") -> 1.0114421 | I19: =IFERROR((1+I17)/(1+I18),"-") -> 0.97668974 | ... N19: =IFERROR((1+N17)/(1+N18),"-") -> 1.0018422

Sheet Selic
A1: Selic Hoje
A2: 0.1475

Sheet Cadastro_Acoes
A1: Ticker | B1: Empresa | C1: Setor | D1: Subsetor
A2: BBAS3 | B2: Banco do Brasil S.A. | C2: Intermediários Financeiros | D2: Bancos
A3: BBSE3 | B3: BB Seguridade | C3: Previdência e Seguros | D3: Seguradoras
A4: BPAC11 | B4: Banco BTG Pactual S.A. | C4: Intermediários Financeiros | D4: Bancos
A5: EGIE3 | B5: Engie Brasil | C5: Energia Elétrica | D5: Energia Elétrica
A6: ELET6 | B6: Centrais Eletricas Brasileiras S.A. | C6: Energia Elétrica | D6: Energia Elétrica
A7: IVVB11 | B7: iShares S&P 500 FIC de Fundo de Indice IE | C7: Fundos de índice | D7: Ações de mercado externo
A8: PRIO3 | B8: Petro Rio S.A. | C8: Petróleo, Gás e Biocombustíveis | D8: Exploração, Refino e Distribuição
A9: USTK11 | B9: Investo ETF MSCI US Technology | C9: Fundos de índice | D9: Ações de mercado externo | Tecnologia
A10: VALE3 | B10: Vale S.A. | C10: Mineração | D10: Minerais Metálicos
A11: LFT | B11: Letra Financeira do Tesouro - Pós Fixado | C11: Títulos Públicos | D11: Títulos Públicos
A12: Caixa | B12: Banco C/C | C12: Caixa | D12: Caixa
... A15: AXIA6 | B15: Centrais Eletricas Brasileiras S.A. | C15: Energia Elétrica | D15: Energia Elétrica
